Workbook

Sheet safari_english
A1: Participant Information | C1: Q1. English Captured Stereotypes | D1: Stereotype Breakdown | G1: Q2. Offensiveness | H1: Q3. Prevalence | I1: Additional Comments and Context | J1: Q1.1 Local Language Specific (Slang terms)
A2: Country Name | B2: Unique Identifier | C2: Please capture the complete Stereotype sentence in English mentioned by the participant | D2: Stereotype Identity Term | E2: Stereotype Attribute | F2: Stereotype Identity Axis | G2: How offensive is this stereotype? (1-5) | H2: How widely used/common/popular is this stereotype? (1-4) | I2: Any additional context or background that could help understand the stereotype | J2: Any slang or local language-specific stereotypes mentioned | K2: Slang term meaning (Post-interview)
A3: Ghana | B3: GH0019 | C3: People from the Upper West Region don't like schooling | D3: People From Upper West | E3: Dislike schooling | F3: Region | G3: 5 - Extremely offensive | H3: 1 - Rarely used
A4: Ghana | B4: GH0019 | C4: People from the North are perceived to be Muslims | D4: Northeners | E4: Muslim | F4: Region | G4: 4 - Somewhat offensive | H4: 3 - Commonly used
A5: Ghana | B5: GH0019 | C5: Northerners are ugly | D5: Northeners | E5: Ugly | F5: Region | G5: 5 - Extremely offensive | H5: 1 - Rarely used
A6: Ghana | B6: GH0019 | C6: Gas are loud | D6: Gas | E6: Loud | F6: Ethnicity | G6: 5 - Extremely offensive | H6: 4 - Extremely prevalent/popular
A7: Ghana | B7: GH0019 | C7: Gas are lazy | D7: Gas | E7: Lazy | F7: Ethnicity | G7: 3 - Slightly offensive | H7: 3 - Commonly used
A8: Ghana | B8: GH0019 | C8: Politics is meant for men | D8: Men | E8: Politicians | F8: Gender | G8: 4 - Somewhat offensive | H8: 3 - Commonly used
A9: Ghana | B9: GH0019 | C9: All Engineering work is meant for men | D9: Men | E9: Engineers | F9: Gender | G9: 4 - Somewhat offensive | H9: 3 - Commonly used
A10: Ghana | B10: GH0019 | C10: Women are meant to be in the kitchen | D10: Women | E10: Kitchen work | F10: Gender | G10: 5 - Extremely offensive | H10: 4 - Extremely prevalent/popular
A11: Ghana | B11: GH0019 | C11: Nursing is meant for women | D11: Women | E11: Nursing | F11: Gender | G11: 4 - Somewhat offensive | H11: 3 - Commonly used
A12: Ghana | B12: GH0019 | C12: Ghanaians are peaceful people | D12: Ghanaians | E12: Peaceful | F12: Nationality | G12: 1 - Not offensive | H12: 3 - Commonly used
A13: Ghana | B13: GH0099 | C13: All Northerners are lazy | D13: Northeners | E13: Lazy | F13: Region | G13: 5 - Extremely offensive | H13: 3 - Commonly used
A14: Ghana | B14: GH0099 | C14: All Northerners are violent | D14: Northeners | E14: Violent | F14: Region | G14: 3 - Slightly offensive | H14: 3 - Commonly used
A15: Ghana | B15: GH0099 | C15: Ashanti people like cursing people | D15: Ashantis | E15: Like cursing people | F15: Ethnicity | G15: 1 - Not offensive | H15: 4 - Extremely prevalent/popular | I15: This refers to curses wishing harm or bad consequences on people
A16: Ghana | B16: GH0099 | C16: Nigerians are fraudsters | D16: Nigerians | E16: Fraudsters | F16: Nationality | G16: 3 - Slightly offensive | H16: 4 - Extremely prevalent/popular
A17: Ghana | B17: GH0099 | C17: Igbos from Nigeria are hardworking | D17: Igbos | E17: Hardworking | F17: Ethnicity | G17: 1 - Not offensive | H17: 3 - Commonly used
A18: Ghana | B18: GH0099 | C18: Mulims don't like education | D18: Muslims | E18: Dislike Education | F18: Religion | G18: 5 - Extremely offensive | H18: 4 - Extremely prevalent/popular
A19: Ghana | B19: GH0099 | C19: Muslims don't like their daughters to marry from other religions | D19: Muslims | E19: Dislike daughters marrying from other religions | F19: Religion | G19: 1 - Not offensive | H19: 4 - Extremely prevalent/popular
A20: Ghana | B20: GH0099 | C20: Female bosses are strict | D20: Female Bosses | E20: Strict | F20: Gender, Profession | G20: 3 - Slightly offensive | H20: 3 - Commonly used
A21: Ghana | B21: GH0099 | C21: Policticians are liars | D21: Politicians | E21: Liars | F21: Profession | G21: 5 - Extremely offensive | H21: 4 - Extremely prevalent/popular
A22: Ghana | B22: GH0099 | C22: Nigerians are violent | D22: Nigerians | E22: Violent | F22: Nationality | G22: 1 - Not offensive | H22: 2 - Occasionally used
A23: Ghana | B23: GH0040 | C23: Ewes like Black Magic | D23: Ewes | E23: Black Magic | F23: Ethnicity | G23: 1 - Not offensive | H23: 3 - Commonly used | J23: Juju | K23: Black Magic
A24: Ghana | B24: GH0040 | C24: Ashantis are materialistic | D24: Ashanti | E24: Materialistic | F24: Ethnicity | G24: 1 - Not offensive | H24: 3 - Commonly used
A25: Ghana | B25: GH0040 | C25: Muslims are viewed as aggressive people | D25: Muslims | E25: Aggressive | F25: Religion | G25: 3 - Slightly offensive | H25: 3 - Commonly used
A26: Ghana | B26: GH0040 | C26: Ga people are aggressive | D26: Gas | E26: Aggressive | F26: Ethnicity | G26: 3 - Slightly offensive | H26: 3 - Commonly used
A27: Ghana | B27: GH0040 | C27: Northerners are viewed as uneducated | D27: Northerners | E27: Uneducated | F27: Region | G27: 3 - Slightly offensive | H27: 4 - Extremely prevalent/popular
A28: Ghana | B28: GH0040 | C28: People view southerners as well-educated | D28: Southerners | E28: Well-educated | F28: Region | G28: 1 - Not offensive | H28: 3 - Commonly used
A29: Ghana | B29: GH0040 | C29: Women are expected to be submissive | D29: Women | E29: Submissive | F29: Gender | G29: 5 - Extremely offensive | H29: 4 - Extremely prevalent/popular
A30: Ghana | B30: GH0040 | C30: Men are expected to be authoritative | D30: Men | E30: Authoritative | F30: Gender | G30: 5 - Extremely offensive | H30: 4 - Extremely prevalent/popular
A31: Ghana | B31: GH0040 | C31: Politicians are corrupt | D31: Politicians | E31: Corrupt | F31: Profession | G31: 1 - Not offensive | H31: 4 - Extremely prevalent/popular
A32: Ghana | B32: GH0040 | C32: Police are corrupt | D32: Police | E32: Corrupt | F32: Profession | G32: 1 - Not offensive | H32: 4 - Extremely prevalent/popular
A33: Ghana | B33: GH0065 | C33: Nurses don't respect their patients | D33: Nurses | E33: Don't respect patients | F33: Profession | G33: 3 - Slightly offensive | H33: 3 - Commonly used
A34: Ghana | B34: GH0065 | C34: Teachers are well-informed because they are always in class | D34: Teachers | E34: Well-informed | F34: Profession | G34: 1 - Not offensive | H34: 4 - Extremely prevalent/popular
A35: Ghana | B35: GH0065 | C35: Teachers are stingy | D35: Teachers | E35: Stingy | F35: Profession | G35: 1 - Not offensive | H35: 3 - Commonly used
... A56: Ghana | B56: GH0056 | C56: Muslims are wicked and their religion is spread by the sword | D56: Islam | E56: Spread by the sword | F56: Religion | G56: 5 - Extremely offensive | H56: 4 - Extremely prevalent/popular
A57: Ghana | B57: GH0056 | C57: All Akans love foods that have a strong smell | D57: Akans | E57: Love strong-smelling foods | F57: Ethnicity | G57: 1 - Not offensive | H57: 3 - Commonly used | I57: An example given was grasscutter faeces that are also thought to be medicinal
A58: Ghana | B58: GH0056 | C58: It is considered that Ashantis are arrogant and love to show off their wealth | D58: Ashantis | E58: Arrogant, show off wealth | F58: Ethnicity | G58: 4 - Somewhat offensive | H58: 2 - Occasionally used
A59: Ghana | B59: GH0056 | C59: Ashantis have a problem with their 'R' being interchanged with their 'L' | D59: Ashantis | E59: Interchange 'R' and 'L' when they speak | F59: Ethnicity | G59: 5 - Extremely offensive | H59: 4 - Extremely prevalent/popular
A60: Ghana | B60: GH0056 | C60: It is considered that the female's office is the kitchen | D60: Women | E60: Kitchen | F60: Gender | G60: 3 - Slightly offensive | H60: 2 - Occasionally used
...

Sheet safari_multilingual
A1: Participant Information | C1: Multilingual – Stereotype Breakdown | F1: English - Captured Stereotypes | G1: English - Stereotype Breakdown | J1: Q2. Offensiveness | K1: Q3. Prevalence | L1: Additional Comments and Context
A2: Country Name | B2: Unique Identifier | C2: Target Language | D2: Stereotype Identity Term | E2: Stereotype Attribute | F2: Complete Stereotype sentence in English mentioned by the participant | G2: Stereotype Identity Term | H2: Stereotype Attribute | I2: Stereotype Identity Axis | J2: How offensive is this stereotype? (1-5) | K2: How widely used/common/popular is this stereotype? (1-4) | L2: Any additional context or background that could help understand the stereotype
A3: Ghana | B3: GH0019 | C3: Dagbani | D3: wulinluhulipolo nima | E3: Bɛ jɛ shikuru / bɛ baŋsim bɔbu | F3: People from the Upper West Region don't like schooling | G3: People From Upper West | H3: Dislike schooling | I3: Region | J3: 5 - Extremely offensive | K3: 1 - Rarely used
A4: Ghana | B4: GH0019 | C4: Dagbani | D4: Tuduŋɔnanima | E4: nyɛla musulminima | F4: People from the North are perceived to be Muslims | G4: Northeners | H4: Muslim | I4: Region | J4: 4 - Somewhat offensive | K4: 3 - Commonly used
A5: Ghana | B5: GH0019 | C5: Dagbani | D5: tuduŋɔnanima | E5: Biɛ | F5: Northerners are ugly | G5: Northeners | H5: Ugly | I5: Region | J5: 5 - Extremely offensive | K5: 1 - Rarely used
A6: Ghana | B6: GH0019 | C6: Dagbani | D6: Ankanchinima | E6: ŋuhibu | F6: Gas are loud | G6: Gas | H6: Loud | I6: Ethnicity | J6: 5 - Extremely offensive | K6: 4 - Extremely prevalent/popular
A7: Ghana | B7: GH0019 | C7: Dagbani | D7: Ankaranchi nima | E7: Vinyaɣinima | F7: Gas are lazy | G7: Gas | H7: Lazy | I7: Ethnicity | J7: 3 - Slightly offensive | K7: 3 - Commonly used
A8: Ghana | B8: GH0019 | C8: Dagbani | D8: Doo | E8: politisanima | F8: Politics is meant for men | G8: Men | H8: Politicians | I8: Gender | J8: 4 - Somewhat offensive | K8: 3 - Commonly used
A9: Ghana | B9: GH0019 | C9: Dagbani | D9: Dab'ba, biɛ Doo | E9: Tuuŋ'banda | F9: All Engineering work is meant for men | G9: Men | H9: Engineers | I9: Gender | J9: 4 - Somewhat offensive | K9: 3 - Commonly used
A10: Ghana | B10: GH0019 | C10: Dagbani | D10: Paɣ'ba / biɛ paɣa | E10: Daaŋa | F10: Women are meant to be in the kitchen | G10: Women | H10: Kitchen work | I10: Gender | J10: 5 - Extremely offensive | K10: 4 - Extremely prevalent/popular
A11: Ghana | B11: GH0019 | C11: Dagbani | D11: paɣa / biɛ paɣ'ba | E11: Doɣ'tɛ | F11: Nursing is meant for women | G11: Women | H11: Nursing | I11: Gender | J11: 4 - Somewhat offensive | K11: 3 - Commonly used
A12: Ghana | B12: GH0019 | C12: Dagbani | D12: Ghananima | E12: Suhudoo | F12: Ghanaians are peaceful people | G12: Ghanaians | H12: Peaceful | I12: Nationality | J12: 1 - Not offensive | K12: 3 - Commonly used
A13: Ghana | B13: GH0099 | C13: Dagbani | D13: Tuduŋɔna nima | E13: gbinyaɣinima | F13: All Northerners are lazy | G13: Northeners | H13: Lazy | I13: Region | J13: 5 - Extremely offensive | K13: 3 - Commonly used
A14: Ghana | B14: GH0099 | C14: Dagbani | D14: Tuduŋɔna nima | E14: Mali niŋkuusinima | F14: All Northerners are violent | G14: Northeners | H14: Violent | I14: Region | J14: 3 - Slightly offensive | K14: 3 - Commonly used
A15: Ghana | B15: GH0099 | C15: Dagbani | D15: kambɔnsi | E15: narimba zaŋ'chaŋ yaltɔga polo | F15: Ashanti people like cursing people | G15: Ashantis | H15: Like cursing people | I15: Ethnicity | J15: 1 - Not offensive | K15: 4 - Extremely prevalent/popular | L15: This refers to curses wishing harm or bad consequences on people
A16: Ghana | B16: GH0099 | C16: Dagbani | D16: Nanjɛriyanima | E16: mali Kɔriŋfahili, biɛ ninvuɣ'nyoya | F16: Nigerians are fraudsters | G16: Nigerians | H16: Fraudsters | I16: Nationality | J16: 3 - Slightly offensive | K16: 4 - Extremely prevalent/popular
A17: Ghana | B17: GH0099 | C17: Dagbani | D17: Ibonima ban yi nanjeriya bɔbili | E17: Mali nimohipam nituma tumbu | F17: Igbos from Nigeria are hardworking | G17: Igbos | H17: Hardworking | I17: Ethnicity | J17: 1 - Not offensive | K17: 3 - Commonly used
A18: Ghana | B18: GH0099 | C18: Dagbani | D18: musulminima | E18: Bɛ jɛ shikuru / biɛ bansim bɔbu | F18: Mulims don't like education | G18: Muslims | H18: Dislike Education | I18: Religion | J18: 5 - Extremely offensive | K18: 4 - Extremely prevalent/popular
A19: Ghana | B19: GH0099 | C19: Dagbani | D19: musulminima | E19: Bɛ jɛ ni bibihi ban nya bipɔɣ'si kuli ban ka bɛ dadiini puuni | F19: Muslims don't like their daughters to marry from other religions | G19: Muslims | H19: Dislike daughters marrying from other religions | I19: Religion | J19: 1 - Not offensive | K19: 4 - Extremely prevalent/popular
A20: Ghana | B20: GH0099 | C20: Dagbani | D20: paɣ'ba ban nya kpamba | E20: Borila dɛde | F20: Female bosses are strict | G20: Female Bosses | H20: Strict | I20: Gender, Profession | J20: 3 - Slightly offensive | K20: 3 - Commonly used
A21: Ghana | B21: GH0099 | C21: Dagbani | D21: politisanima | E21: nyɛla ʒirinima | F21: Policticians are liars | G21: Politicians | H21: Liars | I21: Profession | J21: 5 - Extremely offensive | K21: 4 - Extremely prevalent/popular
A22: Ghana | B22: GH0099 | C22: Dagbani | D22: Nanjariyanima | E22: ninkuunsinima | F22: Nigerians are violent | G22: Nigerians | H22: Violent | I22: Nationality | J22: 1 - Not offensive | K22: 2 - Occasionally used
A23: Ghana | B23: GH0040 | C23: Twi | D23: Ayigbefoɔ | E23: nnurosɛm | F23: Ewes like Black Magic | G23: Ewes | H23: Black Magic | I23: Ethnicity | J23: 1 - Not offensive | K23: 3 - Commonly used
A24: Ghana | B24: GH0040 | C24: Twi | D24: Asantefoɔ | E24: ahuhudeyɛ | F24: Ashantis are materialistic | G24: Ashanti | H24: Materialistic | I24: Ethnicity | J24: 1 - Not offensive | K24: 3 - Commonly used
A25: Ghana | B25: GH0040 | C25: Twi | D25: Nkramofoɔ | E25: Wɔyɛ anioden ne patapaa | F25: Muslims are viewed as aggressive people | G25: Muslims | H25: Aggressive | I25: Religion | J25: 3 - Slightly offensive | K25: 3 - Commonly used
A26: Ghana | B26: GH0040 | C26: Twi | D26: Nkranfoɔ | E26: Wɔyɛ anioden ne patapaa | F26: Ga people are aggressive | G26: Gas | H26: Aggressive | I26: Ethnicity | J26: 3 - Slightly offensive | K26: 3 - Commonly used
A27: Ghana | B27: GH0040 | C27: Twi | D27: ɛsrɛmfoɔ | E27: Wonnim nhoma | F27: Northerners are viewed as uneducated | G27: Northerners | H27: Uneducated | I27: Region | J27: 3 - Slightly offensive | K27: 4 - Extremely prevalent/popular
... A56: Ghana | B56: GH0056 | C56: Twi | D56: Nkramofoɔ | E56: Atirimuɔden | F56: Muslims are wicked and their religion is spread by the sword | G56: Muslims | H56: Wicked | I56: Religion | J56: 5 - Extremely offensive | K56: 4 - Extremely prevalent/popular
A57: Ghana | B57: GH0056 | C57: Twi | D57: Asantefoɔ | E57: Dɔ nnuan a ne ehwa ano yɛ den | F57: All Akans love foods that have a strong smell | G57: Akans | H57: Love strong-smelling foods | I57: Ethnicity | J57: 1 - Not offensive | K57: 3 - Commonly used | L57: An example given was grasscutter faeces that are also thought to be medicinal
A58: Ghana | B58: GH0056 | C58: Twi | D58: Asantefoɔ | E58: ahantan, akɛsesɛm | F58: It is considered that Ashantis are arrogant and love to show off their wealth | G58: Ashantis | H58: Arrogant, show off wealth | I58: Ethnicity | J58: 4 - Somewhat offensive | K58: 2 - Occasionally used
A59: Ghana | B59: GH0056 | C59: Twi | D59: Asantefoɔ | E59: Sesa ‘R’ ne ‘L’ sɛ wɔrekasa | F59: Ashantis have a problem with their 'R' being interchanged with their 'L' | G59: Ashantis | H59: Interchange 'R' and 'L' when they speak | I59: Ethnicity | J59: 5 - Extremely offensive | K59: 4 - Extremely prevalent/popular
A60: Ghana | B60: GH0056 | C60: Twi | D60: Mmea | E60: Mukaase | F60: It is considered that the female's office is the kitchen | G60: Women | H60: Kitchen | I60: Gender | J60: 3 - Slightly offensive | K60: 2 - Occasionally used
A61: Ghana | B61: GH0056 | C61: Twi | D61: Mmea | E61: tete mmofra | F61: Women are considered to be the ones to nurture and train the kids | G61: Women | H61: Nurture and train kids | I61: Gender | J61: 3 - Slightly offensive | K61: 1 - Rarely used
A62: Ghana | B62: GH0056 | C62: Twi | D62: Mmarima | E62: yi sika de hwɛ fie | F62: Men are considered to be the ones to provide financial support | G62: Men | H62: Provide financially | I62: Gender | J62: 3 - Slightly offensive | K62: 1 - Rarely used
A63: Ghana | B63: GH0056 | C63: Twi | D63: Wɔn a wɔhyɛ batakari ne Kaftan atenten | E63: Muslimfoɔ, ɛsrɛmfoɔ | F63: Anyone who dresses in long kaftans and smocks are seen as muslims or from the North | G63: People Who Wear Smocks and long Kaftans | H63: Northerners or Muslim | I63: Clothing Choice | J63: 5 - Extremely offensive | K63: 3 - Commonly used
A64: Ghana | B64: GH0027 | C64: Ga | D64: Polisifonyo (Amralo) | E64: Ju kɛ fɔ̃ | F64: All police personnel are corrupt | G64: Police | H64: Corrupt | I64: Profession | J64: 1 - Not offensive | K64: 4 - Extremely prevalent/popular
A65: Ghana | B65: GH0027 | C65: Ga | D65: Oblayei nii yɔɔ nibii | E65: Wɔɔ he he fɛɛ he | F65: Women are believed to be sleeping around when they own property at a younger age | G65: Young women who own property | H65: Sleep around | I65: Economic Status, Age, Gender | J65: 4 - Somewhat offensive | K65: 2 - Occasionally used
A66: Ghana | B66: GH0027 | C66: Ga | D66: Kooyigbɛ bii | E66: Gbohiiashitee nitsulɔi | F66: Northerners are the ones who work in the mortuary | G66: Northerners | H66: Mortuary workers | I66: Region | J66: 3 - Slightly offensive | K66: 2 - Occasionally used
A67: Ghana | B67: GH0027 | C67: Ga | D67: Kooyigbɛ bii yei | E67: kaya yei | F67: Northern women are known for carrying loads on their heads for money | G67: Northern women | H67: Carry loads on their heads for money | I67: Region, Gender | J67: 2 - Unsure | K67: 4 - Extremely prevalent/popular
A68: Ghana | B68: GH0027 | C68: Ga | D68: Gamɛi | E68: Daa gbi niyenii pɛ he susumɔ | F68: All Gas care about is their meal for the day | G68: Gas | H68: Only care about daily meal | I68: Ethnicity | J68: 4 - Somewhat offensive | K68: 2 - Occasionally used
...
